[2024-08-19T07:48:25.825+0000] {local_task_job_runner.py:120} INFO - ::group::Pre task execution logs
[2024-08-19T07:48:25.856+0000] {taskinstance.py:2076} INFO - Dependencies all met for dep_context=non-requeueable deps ti=<TaskInstance: Weather_Data_Extraction.check_inserted manual__2024-08-19T07:48:16.641393+00:00 [queued]>
[2024-08-19T07:48:25.872+0000] {taskinstance.py:2076} INFO - Dependencies all met for dep_context=requeueable deps ti=<TaskInstance: Weather_Data_Extraction.check_inserted manual__2024-08-19T07:48:16.641393+00:00 [queued]>
[2024-08-19T07:48:25.874+0000] {taskinstance.py:2306} INFO - Starting attempt 1 of 1
[2024-08-19T07:48:26.092+0000] {taskinstance.py:2330} INFO - Executing <Task(BranchPythonOperator): check_inserted> on 2024-08-19 07:48:16.641393+00:00
[2024-08-19T07:48:26.100+0000] {warnings.py:112} WARNING - /home/***/.local/lib/python3.12/site-packages/***/task/task_runner/standard_task_runner.py:61: DeprecationWarning: This process (pid=305) is multi-threaded, use of fork() may lead to deadlocks in the child.
  pid = os.fork()

[2024-08-19T07:48:26.102+0000] {standard_task_runner.py:63} INFO - Started process 307 to run task
[2024-08-19T07:48:26.101+0000] {standard_task_runner.py:90} INFO - Running: ['***', 'tasks', 'run', 'Weather_Data_Extraction', 'check_inserted', 'manual__2024-08-19T07:48:16.641393+00:00', '--job-id', '1372', '--raw', '--subdir', 'DAGS_FOLDER/Data_Weather_Extraction.py', '--cfg-path', '/tmp/tmpfnoyhy3g']
[2024-08-19T07:48:26.103+0000] {standard_task_runner.py:91} INFO - Job 1372: Subtask check_inserted
[2024-08-19T07:48:26.185+0000] {task_command.py:426} INFO - Running <TaskInstance: Weather_Data_Extraction.check_inserted manual__2024-08-19T07:48:16.641393+00:00 [running]> on host ubuntu
[2024-08-19T07:48:26.401+0000] {taskinstance.py:2648} INFO - Exporting env vars: AIRFLOW_CTX_DAG_EMAIL='dohung24112002@gmail.com' AIRFLOW_CTX_DAG_OWNER='Ducky' AIRFLOW_CTX_DAG_ID='Weather_Data_Extraction' AIRFLOW_CTX_TASK_ID='check_inserted' AIRFLOW_CTX_EXECUTION_DATE='2024-08-19T07:48:16.641393+00:00' AIRFLOW_CTX_TRY_NUMBER='1' AIRFLOW_CTX_DAG_RUN_ID='manual__2024-08-19T07:48:16.641393+00:00'
[2024-08-19T07:48:26.405+0000] {taskinstance.py:430} INFO - ::endgroup::
[2024-08-19T07:48:26.437+0000] {baseoperator.py:400} WARNING - BranchPythonOperator.execute cannot be called outside TaskInstance!
[2024-08-19T07:48:26.439+0000] {logging_mixin.py:188} INFO - 2024-08-18
[2024-08-19T07:48:26.440+0000] {logging_mixin.py:188} INFO - <class 'pendulum.date.Date'>
[2024-08-19T07:48:26.462+0000] {base.py:84} INFO - Using connection ID 'snowflake_conn_raw' for task execution.
[2024-08-19T07:48:26.465+0000] {connection.py:399} INFO - Snowflake Connector for Python Version: 3.10.1, Python Version: 3.12.4, Platform: Linux-5.15.153.1-microsoft-standard-WSL2-x86_64-with-glibc2.36
[2024-08-19T07:48:26.467+0000] {connection.py:1239} INFO - This connection is in OCSP Fail Open Mode. TLS Certificates would be checked for validity and revocation status. Any other Certificate Revocation related exceptions or OCSP Responder failures would be disregarded in favor of connectivity.
[2024-08-19T07:48:27.645+0000] {logging_mixin.py:188} INFO - Connected Successfully!
[2024-08-19T07:48:27.646+0000] {logging_mixin.py:188} INFO - 
        SELECT MAX(INPUT_DATE) FROM RAW_WEATHER_DATA;
    
[2024-08-19T07:48:27.863+0000] {cursor.py:1149} INFO - Number of results in first chunk: 1
[2024-08-19T07:48:27.869+0000] {logging_mixin.py:188} INFO - 2024-08-17
[2024-08-19T07:48:27.870+0000] {logging_mixin.py:188} INFO - <class 'pendulum.date.Date'>
[2024-08-19T07:48:27.873+0000] {connection.py:762} INFO - closed
[2024-08-19T07:48:27.993+0000] {connection.py:768} INFO - No async queries seem to be running, deleting session
[2024-08-19T07:48:28.137+0000] {logging_mixin.py:188} INFO - invoke_lambda_task task will execute
[2024-08-19T07:48:28.140+0000] {python.py:237} INFO - Done. Returned value was: invoke_lambda_task
[2024-08-19T07:48:28.141+0000] {branch.py:36} INFO - Branch into invoke_lambda_task
[2024-08-19T07:48:28.142+0000] {skipmixin.py:178} INFO - Following branch invoke_lambda_task
[2024-08-19T07:48:28.144+0000] {taskinstance.py:441} INFO - ::group::Post task execution logs
[2024-08-19T07:48:28.166+0000] {taskinstance.py:2905} ERROR - Task failed with exception
Traceback (most recent call last):
  File "/home/airflow/.local/lib/python3.12/site-packages/airflow/models/taskinstance.py", line 465, in _execute_task
    result = _execute_callable(context=context, **execute_callable_kwargs)
             ^^^^^^^^^^^^^^^^^^^^^^^^^^^^^^^^^^^^^^^^^^^^^^^^^^^^^^^^^^^^^
  File "/home/airflow/.local/lib/python3.12/site-packages/airflow/models/taskinstance.py", line 432, in _execute_callable
    return execute_callable(context=context, **execute_callable_kwargs)
           ^^^^^^^^^^^^^^^^^^^^^^^^^^^^^^^^^^^^^^^^^^^^^^^^^^^^^^^^^^^^
  File "/home/airflow/.local/lib/python3.12/site-packages/airflow/models/baseoperator.py", line 401, in wrapper
    return func(self, *args, **kwargs)
           ^^^^^^^^^^^^^^^^^^^^^^^^^^^
  File "/home/airflow/.local/lib/python3.12/site-packages/airflow/operators/python.py", line 269, in execute
    return self.do_branch(context, super().execute(context))
           ^^^^^^^^^^^^^^^^^^^^^^^^^^^^^^^^^^^^^^^^^^^^^^^^^
  File "/home/airflow/.local/lib/python3.12/site-packages/airflow/operators/branch.py", line 37, in do_branch
    self.skip_all_except(context["ti"], branches_to_execute)
  File "/home/airflow/.local/lib/python3.12/site-packages/airflow/models/skipmixin.py", line 215, in skip_all_except
    raise AirflowException(
airflow.exceptions.AirflowException: 'branch_task_ids' must contain only valid task_ids. Invalid tasks found: {'invoke_lambda_task'}.
[2024-08-19T07:48:28.180+0000] {taskinstance.py:1206} INFO - Marking task as FAILED. dag_id=Weather_Data_Extraction, task_id=check_inserted, run_id=manual__2024-08-19T07:48:16.641393+00:00, execution_date=20240819T074816, start_date=20240819T074825, end_date=20240819T074828
[2024-08-19T07:48:28.217+0000] {base.py:84} INFO - Using connection ID 'smtp_default' for task execution.
[2024-08-19T07:48:28.219+0000] {email.py:271} INFO - Email alerting: attempt 1
[2024-08-19T07:48:28.232+0000] {base.py:84} INFO - Using connection ID 'smtp_default' for task execution.
[2024-08-19T07:48:28.233+0000] {email.py:271} INFO - Email alerting: attempt 1
[2024-08-19T07:48:28.235+0000] {taskinstance.py:879} ERROR - Failed to send email to: dohung24112002@gmail.com
Traceback (most recent call last):
  File "/home/airflow/.local/lib/python3.12/site-packages/airflow/models/taskinstance.py", line 2479, in _run_raw_task
    self._execute_task_with_callbacks(context, test_mode, session=session)
  File "/home/airflow/.local/lib/python3.12/site-packages/airflow/models/taskinstance.py", line 2676, in _execute_task_with_callbacks
    result = self._execute_task(context, task_orig)
             ^^^^^^^^^^^^^^^^^^^^^^^^^^^^^^^^^^^^^^
  File "/home/airflow/.local/lib/python3.12/site-packages/airflow/models/taskinstance.py", line 2701, in _execute_task
    return _execute_task(self, context, task_orig)
           ^^^^^^^^^^^^^^^^^^^^^^^^^^^^^^^^^^^^^^^
  File "/home/airflow/.local/lib/python3.12/site-packages/airflow/models/taskinstance.py", line 465, in _execute_task
    result = _execute_callable(context=context, **execute_callable_kwargs)
             ^^^^^^^^^^^^^^^^^^^^^^^^^^^^^^^^^^^^^^^^^^^^^^^^^^^^^^^^^^^^^
  File "/home/airflow/.local/lib/python3.12/site-packages/airflow/models/taskinstance.py", line 432, in _execute_callable
    return execute_callable(context=context, **execute_callable_kwargs)
           ^^^^^^^^^^^^^^^^^^^^^^^^^^^^^^^^^^^^^^^^^^^^^^^^^^^^^^^^^^^^
  File "/home/airflow/.local/lib/python3.12/site-packages/airflow/models/baseoperator.py", line 401, in wrapper
    return func(self, *args, **kwargs)
           ^^^^^^^^^^^^^^^^^^^^^^^^^^^
  File "/home/airflow/.local/lib/python3.12/site-packages/airflow/operators/python.py", line 269, in execute
    return self.do_branch(context, super().execute(context))
           ^^^^^^^^^^^^^^^^^^^^^^^^^^^^^^^^^^^^^^^^^^^^^^^^^
  File "/home/airflow/.local/lib/python3.12/site-packages/airflow/operators/branch.py", line 37, in do_branch
    self.skip_all_except(context["ti"], branches_to_execute)
  File "/home/airflow/.local/lib/python3.12/site-packages/airflow/models/skipmixin.py", line 215, in skip_all_except
    raise AirflowException(
airflow.exceptions.AirflowException: 'branch_task_ids' must contain only valid task_ids. Invalid tasks found: {'invoke_lambda_task'}.

During handling of the above exception, another exception occurred:

Traceback (most recent call last):
  File "/home/airflow/.local/lib/python3.12/site-packages/airflow/models/taskinstance.py", line 1063, in _email_alert
    send_email(task.email, subject, html_content)
  File "/home/airflow/.local/lib/python3.12/site-packages/airflow/utils/email.py", line 80, in send_email
    return backend(
           ^^^^^^^^
  File "/home/airflow/.local/lib/python3.12/site-packages/airflow/utils/email.py", line 154, in send_email_smtp
    send_mime_email(e_from=mail_from, e_to=recipients, mime_msg=msg, conn_id=conn_id, dryrun=dryrun)
  File "/home/airflow/.local/lib/python3.12/site-packages/airflow/utils/email.py", line 273, in send_mime_email
    smtp_conn = _get_smtp_connection(smtp_host, smtp_port, smtp_timeout, smtp_ssl)
                ^^^^^^^^^^^^^^^^^^^^^^^^^^^^^^^^^^^^^^^^^^^^^^^^^^^^^^^^^^^^^^^^^^
  File "/home/airflow/.local/lib/python3.12/site-packages/airflow/utils/email.py", line 317, in _get_smtp_connection
    return smtplib.SMTP(host=host, port=port, timeout=timeout)
           ^^^^^^^^^^^^^^^^^^^^^^^^^^^^^^^^^^^^^^^^^^^^^^^^^^^
  File "/usr/local/lib/python3.12/smtplib.py", line 255, in __init__
    (code, msg) = self.connect(host, port)
                  ^^^^^^^^^^^^^^^^^^^^^^^^
  File "/usr/local/lib/python3.12/smtplib.py", line 341, in connect
    self.sock = self._get_socket(host, port, self.timeout)
                ^^^^^^^^^^^^^^^^^^^^^^^^^^^^^^^^^^^^^^^^^^
  File "/usr/local/lib/python3.12/smtplib.py", line 312, in _get_socket
    return socket.create_connection((host, port), timeout,
           ^^^^^^^^^^^^^^^^^^^^^^^^^^^^^^^^^^^^^^^^^^^^^^^
  File "/usr/local/lib/python3.12/socket.py", line 853, in create_connection
    raise exceptions[0]
  File "/usr/local/lib/python3.12/socket.py", line 838, in create_connection
    sock.connect(sa)
ConnectionRefusedError: [Errno 111] Connection refused

During handling of the above exception, another exception occurred:

Traceback (most recent call last):
  File "/home/airflow/.local/lib/python3.12/site-packages/airflow/models/taskinstance.py", line 877, in _handle_failure
    task_instance.email_alert(error, failure_context["task"])
  File "/home/airflow/.local/lib/python3.12/site-packages/airflow/models/taskinstance.py", line 3163, in email_alert
    _email_alert(task_instance=self, exception=exception, task=task)
  File "/home/airflow/.local/lib/python3.12/site-packages/airflow/models/taskinstance.py", line 1065, in _email_alert
    send_email(task.email, subject, html_content_err)
  File "/home/airflow/.local/lib/python3.12/site-packages/airflow/utils/email.py", line 80, in send_email
    return backend(
           ^^^^^^^^
  File "/home/airflow/.local/lib/python3.12/site-packages/airflow/utils/email.py", line 154, in send_email_smtp
    send_mime_email(e_from=mail_from, e_to=recipients, mime_msg=msg, conn_id=conn_id, dryrun=dryrun)
  File "/home/airflow/.local/lib/python3.12/site-packages/airflow/utils/email.py", line 273, in send_mime_email
    smtp_conn = _get_smtp_connection(smtp_host, smtp_port, smtp_timeout, smtp_ssl)
                ^^^^^^^^^^^^^^^^^^^^^^^^^^^^^^^^^^^^^^^^^^^^^^^^^^^^^^^^^^^^^^^^^^
  File "/home/airflow/.local/lib/python3.12/site-packages/airflow/utils/email.py", line 317, in _get_smtp_connection
    return smtplib.SMTP(host=host, port=port, timeout=timeout)
           ^^^^^^^^^^^^^^^^^^^^^^^^^^^^^^^^^^^^^^^^^^^^^^^^^^^
  File "/usr/local/lib/python3.12/smtplib.py", line 255, in __init__
    (code, msg) = self.connect(host, port)
                  ^^^^^^^^^^^^^^^^^^^^^^^^
  File "/usr/local/lib/python3.12/smtplib.py", line 341, in connect
    self.sock = self._get_socket(host, port, self.timeout)
                ^^^^^^^^^^^^^^^^^^^^^^^^^^^^^^^^^^^^^^^^^^
  File "/usr/local/lib/python3.12/smtplib.py", line 312, in _get_socket
    return socket.create_connection((host, port), timeout,
           ^^^^^^^^^^^^^^^^^^^^^^^^^^^^^^^^^^^^^^^^^^^^^^^
  File "/usr/local/lib/python3.12/socket.py", line 853, in create_connection
    raise exceptions[0]
  File "/usr/local/lib/python3.12/socket.py", line 838, in create_connection
    sock.connect(sa)
ConnectionRefusedError: [Errno 111] Connection refused
[2024-08-19T07:48:28.254+0000] {base.py:84} INFO - Using connection ID 'smtp_default' for task execution.
[2024-08-19T07:48:28.257+0000] {warnings.py:112} WARNING - /home/***/.local/lib/python3.12/site-packages/***/utils/context.py:212: AirflowContextDeprecationWarning: Accessing 'execution_date' from the template is deprecated and will be removed in a future version. Please use 'data_interval_start' or 'logical_date' instead.
  warnings.warn(_create_deprecation_warning(key, self._deprecation_replacements[key]))

[2024-08-19T07:48:31.640+0000] {logging_mixin.py:188} INFO - Alert email has been sent successfully!
[2024-08-19T07:48:31.856+0000] {standard_task_runner.py:110} ERROR - Failed to execute job 1372 for task check_inserted ('branch_task_ids' must contain only valid task_ids. Invalid tasks found: {'invoke_lambda_task'}.; 307)
[2024-08-19T07:48:31.873+0000] {local_task_job_runner.py:240} INFO - Task exited with return code 1
[2024-08-19T07:48:31.903+0000] {taskinstance.py:3503} INFO - 0 downstream tasks scheduled from follow-on schedule check
[2024-08-19T07:48:31.910+0000] {local_task_job_runner.py:222} INFO - ::endgroup::
