[2024-08-09T08:46:55.240+0000] {local_task_job_runner.py:120} INFO - ::group::Pre task execution logs
[2024-08-09T08:46:55.259+0000] {taskinstance.py:2076} INFO - Dependencies all met for dep_context=non-requeueable deps ti=<TaskInstance: Weather_Data_Extraction.check_inserted scheduled__2024-08-08T00:00:00+00:00 [queued]>
[2024-08-09T08:46:55.269+0000] {taskinstance.py:2076} INFO - Dependencies all met for dep_context=requeueable deps ti=<TaskInstance: Weather_Data_Extraction.check_inserted scheduled__2024-08-08T00:00:00+00:00 [queued]>
[2024-08-09T08:46:55.269+0000] {taskinstance.py:2306} INFO - Starting attempt 1 of 1
[2024-08-09T08:46:55.493+0000] {taskinstance.py:2330} INFO - Executing <Task(BranchPythonOperator): check_inserted> on 2024-08-08 00:00:00+00:00
[2024-08-09T08:46:55.510+0000] {warnings.py:112} WARNING - /home/***/.local/lib/python3.12/site-packages/***/task/task_runner/standard_task_runner.py:61: DeprecationWarning: This process (pid=940) is multi-threaded, use of fork() may lead to deadlocks in the child.
  pid = os.fork()

[2024-08-09T08:46:55.511+0000] {standard_task_runner.py:63} INFO - Started process 944 to run task
[2024-08-09T08:46:55.513+0000] {standard_task_runner.py:90} INFO - Running: ['***', 'tasks', 'run', 'Weather_Data_Extraction', 'check_inserted', 'scheduled__2024-08-08T00:00:00+00:00', '--job-id', '42', '--raw', '--subdir', 'DAGS_FOLDER/Data_Weather_Extraction.py', '--cfg-path', '/tmp/tmpvtrup8d2']
[2024-08-09T08:46:55.517+0000] {standard_task_runner.py:91} INFO - Job 42: Subtask check_inserted
[2024-08-09T08:46:55.534+0000] {warnings.py:112} WARNING - /home/***/.local/lib/python3.12/site-packages/***/settings.py:195: DeprecationWarning: The sql_alchemy_conn option in [core] has been moved to the sql_alchemy_conn option in [database] - the old setting has been used, but please update your config.
  SQL_ALCHEMY_CONN = conf.get("database", "SQL_ALCHEMY_CONN")

[2024-08-09T08:46:55.575+0000] {task_command.py:426} INFO - Running <TaskInstance: Weather_Data_Extraction.check_inserted scheduled__2024-08-08T00:00:00+00:00 [running]> on host ubuntu
[2024-08-09T08:46:55.679+0000] {taskinstance.py:2648} INFO - Exporting env vars: AIRFLOW_CTX_DAG_OWNER='Ducky' AIRFLOW_CTX_DAG_ID='Weather_Data_Extraction' AIRFLOW_CTX_TASK_ID='check_inserted' AIRFLOW_CTX_EXECUTION_DATE='2024-08-08T00:00:00+00:00' AIRFLOW_CTX_TRY_NUMBER='1' AIRFLOW_CTX_DAG_RUN_ID='scheduled__2024-08-08T00:00:00+00:00'
[2024-08-09T08:46:55.682+0000] {taskinstance.py:430} INFO - ::endgroup::
[2024-08-09T08:46:55.701+0000] {baseoperator.py:400} WARNING - BranchPythonOperator.execute cannot be called outside TaskInstance!
[2024-08-09T08:46:55.702+0000] {logging_mixin.py:188} INFO - 2024-08-08
[2024-08-09T08:46:55.702+0000] {logging_mixin.py:188} INFO - <class 'pendulum.date.Date'>
[2024-08-09T08:46:55.711+0000] {taskinstance.py:441} INFO - ::group::Post task execution logs
[2024-08-09T08:46:55.722+0000] {taskinstance.py:2905} ERROR - Task failed with exception
Traceback (most recent call last):
  File "/home/airflow/.local/lib/python3.12/site-packages/airflow/models/taskinstance.py", line 465, in _execute_task
    result = _execute_callable(context=context, **execute_callable_kwargs)
             ^^^^^^^^^^^^^^^^^^^^^^^^^^^^^^^^^^^^^^^^^^^^^^^^^^^^^^^^^^^^^
  File "/home/airflow/.local/lib/python3.12/site-packages/airflow/models/taskinstance.py", line 432, in _execute_callable
    return execute_callable(context=context, **execute_callable_kwargs)
           ^^^^^^^^^^^^^^^^^^^^^^^^^^^^^^^^^^^^^^^^^^^^^^^^^^^^^^^^^^^^
  File "/home/airflow/.local/lib/python3.12/site-packages/airflow/models/baseoperator.py", line 401, in wrapper
    return func(self, *args, **kwargs)
           ^^^^^^^^^^^^^^^^^^^^^^^^^^^
  File "/home/airflow/.local/lib/python3.12/site-packages/airflow/operators/python.py", line 269, in execute
    return self.do_branch(context, super().execute(context))
                                   ^^^^^^^^^^^^^^^^^^^^^^^^
  File "/home/airflow/.local/lib/python3.12/site-packages/airflow/models/baseoperator.py", line 401, in wrapper
    return func(self, *args, **kwargs)
           ^^^^^^^^^^^^^^^^^^^^^^^^^^^
  File "/home/airflow/.local/lib/python3.12/site-packages/airflow/operators/python.py", line 235, in execute
    return_value = self.execute_callable()
                   ^^^^^^^^^^^^^^^^^^^^^^^
  File "/home/airflow/.local/lib/python3.12/site-packages/airflow/operators/python.py", line 252, in execute_callable
    return self.python_callable(*self.op_args, **self.op_kwargs)
           ^^^^^^^^^^^^^^^^^^^^^^^^^^^^^^^^^^^^^^^^^^^^^^^^^^^^^
  File "/opt/airflow/dags/Data_Weather_Extraction.py", line 33, in check_inserted
    conn = hook.get_conn()
           ^^^^^^^^^^^^^^^
  File "/home/airflow/.local/lib/python3.12/site-packages/airflow/providers/snowflake/hooks/snowflake.py", line 289, in get_conn
    conn_config = self._get_conn_params
                  ^^^^^^^^^^^^^^^^^^^^^
  File "/usr/local/lib/python3.12/functools.py", line 995, in __get__
    val = self.func(instance)
          ^^^^^^^^^^^^^^^^^^^
  File "/home/airflow/.local/lib/python3.12/site-packages/airflow/providers/snowflake/hooks/snowflake.py", line 188, in _get_conn_params
    conn = self.get_connection(self.snowflake_conn_id)  # type: ignore[attr-defined]
           ^^^^^^^^^^^^^^^^^^^^^^^^^^^^^^^^^^^^^^^^^^^
  File "/home/airflow/.local/lib/python3.12/site-packages/airflow/hooks/base.py", line 83, in get_connection
    conn = Connection.get_connection_from_secrets(conn_id)
           ^^^^^^^^^^^^^^^^^^^^^^^^^^^^^^^^^^^^^^^^^^^^^^^
  File "/home/airflow/.local/lib/python3.12/site-packages/airflow/models/connection.py", line 519, in get_connection_from_secrets
    raise AirflowNotFoundException(f"The conn_id `{conn_id}` isn't defined")
airflow.exceptions.AirflowNotFoundException: The conn_id `snowflake_conn_raw` isn't defined
[2024-08-09T08:46:55.728+0000] {taskinstance.py:1206} INFO - Marking task as FAILED. dag_id=Weather_Data_Extraction, task_id=check_inserted, run_id=scheduled__2024-08-08T00:00:00+00:00, execution_date=20240808T000000, start_date=20240809T084655, end_date=20240809T084655
[2024-08-09T08:46:55.745+0000] {standard_task_runner.py:110} ERROR - Failed to execute job 42 for task check_inserted (The conn_id `snowflake_conn_raw` isn't defined; 944)
[2024-08-09T08:46:55.770+0000] {local_task_job_runner.py:240} INFO - Task exited with return code 1
[2024-08-09T08:46:55.805+0000] {taskinstance.py:3503} INFO - 0 downstream tasks scheduled from follow-on schedule check
[2024-08-09T08:46:55.809+0000] {local_task_job_runner.py:222} INFO - ::endgroup::
