[2024-08-16T08:50:23.106+0000] {local_task_job_runner.py:120} INFO - ::group::Pre task execution logs
[2024-08-16T08:50:23.133+0000] {taskinstance.py:2076} INFO - Dependencies all met for dep_context=non-requeueable deps ti=<TaskInstance: Prediction_Model.Call_Prepare_Data_Procedure manual__2024-08-16T08:50:08.517838+00:00 [queued]>
[2024-08-16T08:50:23.149+0000] {taskinstance.py:2076} INFO - Dependencies all met for dep_context=requeueable deps ti=<TaskInstance: Prediction_Model.Call_Prepare_Data_Procedure manual__2024-08-16T08:50:08.517838+00:00 [queued]>
[2024-08-16T08:50:23.150+0000] {taskinstance.py:2306} INFO - Starting attempt 1 of 1
[2024-08-16T08:50:23.175+0000] {taskinstance.py:2330} INFO - Executing <Task(PythonOperator): Call_Prepare_Data_Procedure> on 2024-08-16 08:50:08.517838+00:00
[2024-08-16T08:50:23.190+0000] {warnings.py:112} WARNING - /home/***/.local/lib/python3.12/site-packages/***/task/task_runner/standard_task_runner.py:61: DeprecationWarning: This process (pid=482) is multi-threaded, use of fork() may lead to deadlocks in the child.
  pid = os.fork()

[2024-08-16T08:50:23.193+0000] {standard_task_runner.py:63} INFO - Started process 484 to run task
[2024-08-16T08:50:23.194+0000] {standard_task_runner.py:90} INFO - Running: ['***', 'tasks', 'run', 'Prediction_Model', 'Call_Prepare_Data_Procedure', 'manual__2024-08-16T08:50:08.517838+00:00', '--job-id', '1113', '--raw', '--subdir', 'DAGS_FOLDER/Prediction_Model.py', '--cfg-path', '/tmp/tmptxpo6v12']
[2024-08-16T08:50:23.200+0000] {standard_task_runner.py:91} INFO - Job 1113: Subtask Call_Prepare_Data_Procedure
[2024-08-16T08:50:23.293+0000] {task_command.py:426} INFO - Running <TaskInstance: Prediction_Model.Call_Prepare_Data_Procedure manual__2024-08-16T08:50:08.517838+00:00 [running]> on host ubuntu
[2024-08-16T08:50:23.528+0000] {taskinstance.py:2648} INFO - Exporting env vars: AIRFLOW_CTX_DAG_OWNER='Ducky' AIRFLOW_CTX_DAG_ID='Prediction_Model' AIRFLOW_CTX_TASK_ID='Call_Prepare_Data_Procedure' AIRFLOW_CTX_EXECUTION_DATE='2024-08-16T08:50:08.517838+00:00' AIRFLOW_CTX_TRY_NUMBER='1' AIRFLOW_CTX_DAG_RUN_ID='manual__2024-08-16T08:50:08.517838+00:00'
[2024-08-16T08:50:23.531+0000] {taskinstance.py:430} INFO - ::endgroup::
[2024-08-16T08:50:23.562+0000] {taskinstance.py:441} INFO - ::group::Post task execution logs
[2024-08-16T08:50:23.565+0000] {taskinstance.py:2905} ERROR - Task failed with exception
Traceback (most recent call last):
  File "/home/airflow/.local/lib/python3.12/site-packages/airflow/models/taskinstance.py", line 465, in _execute_task
    result = _execute_callable(context=context, **execute_callable_kwargs)
             ^^^^^^^^^^^^^^^^^^^^^^^^^^^^^^^^^^^^^^^^^^^^^^^^^^^^^^^^^^^^^
  File "/home/airflow/.local/lib/python3.12/site-packages/airflow/models/taskinstance.py", line 432, in _execute_callable
    return execute_callable(context=context, **execute_callable_kwargs)
           ^^^^^^^^^^^^^^^^^^^^^^^^^^^^^^^^^^^^^^^^^^^^^^^^^^^^^^^^^^^^
  File "/home/airflow/.local/lib/python3.12/site-packages/airflow/models/baseoperator.py", line 401, in wrapper
    return func(self, *args, **kwargs)
           ^^^^^^^^^^^^^^^^^^^^^^^^^^^
  File "/home/airflow/.local/lib/python3.12/site-packages/airflow/operators/python.py", line 235, in execute
    return_value = self.execute_callable()
                   ^^^^^^^^^^^^^^^^^^^^^^^
  File "/home/airflow/.local/lib/python3.12/site-packages/airflow/operators/python.py", line 252, in execute_callable
    return self.python_callable(*self.op_args, **self.op_kwargs)
           ^^^^^^^^^^^^^^^^^^^^^^^^^^^^^^^^^^^^^^^^^^^^^^^^^^^^^
  File "/opt/airflow/dags/Prediction_Model.py", line 22, in call_snowflake_procedure
    execution_date = execution_date.strptime('%Y/%m/%d')
                     ^^^^^^^^^^^^^^^^^^^^^^^
AttributeError: 'str' object has no attribute 'strptime'
[2024-08-16T08:50:23.597+0000] {taskinstance.py:1206} INFO - Marking task as FAILED. dag_id=Prediction_Model, task_id=Call_Prepare_Data_Procedure, run_id=manual__2024-08-16T08:50:08.517838+00:00, execution_date=20240816T085008, start_date=20240816T085023, end_date=20240816T085023
[2024-08-16T08:50:23.627+0000] {standard_task_runner.py:110} ERROR - Failed to execute job 1113 for task Call_Prepare_Data_Procedure ('str' object has no attribute 'strptime'; 484)
[2024-08-16T08:50:23.651+0000] {local_task_job_runner.py:240} INFO - Task exited with return code 1
[2024-08-16T08:50:23.680+0000] {taskinstance.py:3503} INFO - 0 downstream tasks scheduled from follow-on schedule check
[2024-08-16T08:50:23.686+0000] {local_task_job_runner.py:222} INFO - ::endgroup::
