[2024-08-14T04:02:02.493+0000] {local_task_job_runner.py:120} INFO - ::group::Pre task execution logs
[2024-08-14T04:02:02.523+0000] {taskinstance.py:2076} INFO - Dependencies all met for dep_context=non-requeueable deps ti=<TaskInstance: Weather_Data_Extraction.check_s3_file backfill__2024-02-09T00:00:00+00:00 [queued]>
[2024-08-14T04:02:02.721+0000] {taskinstance.py:2076} INFO - Dependencies all met for dep_context=requeueable deps ti=<TaskInstance: Weather_Data_Extraction.check_s3_file backfill__2024-02-09T00:00:00+00:00 [queued]>
[2024-08-14T04:02:02.723+0000] {taskinstance.py:2306} INFO - Starting attempt 1 of 1
[2024-08-14T04:02:02.756+0000] {taskinstance.py:2330} INFO - Executing <Task(S3KeySensor): check_s3_file> on 2024-02-09 00:00:00+00:00
[2024-08-14T04:02:02.778+0000] {warnings.py:112} WARNING - /home/***/.local/lib/python3.12/site-packages/***/task/task_runner/standard_task_runner.py:61: DeprecationWarning: This process (pid=1820) is multi-threaded, use of fork() may lead to deadlocks in the child.
  pid = os.fork()

[2024-08-14T04:02:02.780+0000] {standard_task_runner.py:63} INFO - Started process 1822 to run task
[2024-08-14T04:02:02.780+0000] {standard_task_runner.py:90} INFO - Running: ['***', 'tasks', 'run', 'Weather_Data_Extraction', 'check_s3_file', 'backfill__2024-02-09T00:00:00+00:00', '--job-id', '522', '--pool', 'default_pool', '--raw', '--subdir', 'DAGS_FOLDER/Data_Weather_Extraction.py', '--cfg-path', '/tmp/tmptx7cokli']
[2024-08-14T04:02:02.784+0000] {standard_task_runner.py:91} INFO - Job 522: Subtask check_s3_file
[2024-08-14T04:02:02.840+0000] {task_command.py:426} INFO - Running <TaskInstance: Weather_Data_Extraction.check_s3_file backfill__2024-02-09T00:00:00+00:00 [running]> on host ubuntu
[2024-08-14T04:02:02.983+0000] {taskinstance.py:2648} INFO - Exporting env vars: AIRFLOW_CTX_DAG_OWNER='Ducky' AIRFLOW_CTX_DAG_ID='Weather_Data_Extraction' AIRFLOW_CTX_TASK_ID='check_s3_file' AIRFLOW_CTX_EXECUTION_DATE='2024-02-09T00:00:00+00:00' AIRFLOW_CTX_TRY_NUMBER='1' AIRFLOW_CTX_DAG_RUN_ID='backfill__2024-02-09T00:00:00+00:00'
[2024-08-14T04:02:02.985+0000] {taskinstance.py:430} INFO - ::endgroup::
[2024-08-14T04:02:02.998+0000] {baseoperator.py:400} WARNING - S3KeySensor.execute cannot be called outside TaskInstance!
[2024-08-14T04:02:02.999+0000] {s3.py:117} INFO - Poking for key : s3://s3-poc-data-marketplace/Weather_Data/Data_Weather-20240209.csv
[2024-08-14T04:02:03.014+0000] {base.py:84} INFO - Using connection ID 'aws_conn_poc' for task execution.
[2024-08-14T04:02:03.015+0000] {connection_wrapper.py:384} INFO - AWS Connection (conn_id='aws_conn_poc', conn_type='aws') credentials retrieved from login and password.
[2024-08-14T04:02:34.310+0000] {s3.py:117} INFO - Poking for key : s3://s3-poc-data-marketplace/Weather_Data/Data_Weather-20240209.csv
[2024-08-14T04:03:05.084+0000] {s3.py:117} INFO - Poking for key : s3://s3-poc-data-marketplace/Weather_Data/Data_Weather-20240209.csv
[2024-08-14T04:03:35.878+0000] {s3.py:117} INFO - Poking for key : s3://s3-poc-data-marketplace/Weather_Data/Data_Weather-20240209.csv
[2024-08-14T04:04:06.524+0000] {s3.py:117} INFO - Poking for key : s3://s3-poc-data-marketplace/Weather_Data/Data_Weather-20240209.csv
[2024-08-14T04:04:37.226+0000] {s3.py:117} INFO - Poking for key : s3://s3-poc-data-marketplace/Weather_Data/Data_Weather-20240209.csv
[2024-08-14T04:05:08.119+0000] {s3.py:117} INFO - Poking for key : s3://s3-poc-data-marketplace/Weather_Data/Data_Weather-20240209.csv
[2024-08-14T04:05:38.898+0000] {s3.py:117} INFO - Poking for key : s3://s3-poc-data-marketplace/Weather_Data/Data_Weather-20240209.csv
[2024-08-14T04:06:09.478+0000] {s3.py:117} INFO - Poking for key : s3://s3-poc-data-marketplace/Weather_Data/Data_Weather-20240209.csv
[2024-08-14T04:06:40.243+0000] {s3.py:117} INFO - Poking for key : s3://s3-poc-data-marketplace/Weather_Data/Data_Weather-20240209.csv
[2024-08-14T04:07:14.874+0000] {s3.py:117} INFO - Poking for key : s3://s3-poc-data-marketplace/Weather_Data/Data_Weather-20240209.csv
[2024-08-14T04:07:45.847+0000] {s3.py:117} INFO - Poking for key : s3://s3-poc-data-marketplace/Weather_Data/Data_Weather-20240209.csv
[2024-08-14T04:08:16.630+0000] {s3.py:117} INFO - Poking for key : s3://s3-poc-data-marketplace/Weather_Data/Data_Weather-20240209.csv
[2024-08-14T04:08:51.219+0000] {s3.py:117} INFO - Poking for key : s3://s3-poc-data-marketplace/Weather_Data/Data_Weather-20240209.csv
[2024-08-14T04:09:26.176+0000] {s3.py:117} INFO - Poking for key : s3://s3-poc-data-marketplace/Weather_Data/Data_Weather-20240209.csv
[2024-08-14T04:09:56.753+0000] {s3.py:117} INFO - Poking for key : s3://s3-poc-data-marketplace/Weather_Data/Data_Weather-20240209.csv
[2024-08-14T04:10:27.355+0000] {s3.py:117} INFO - Poking for key : s3://s3-poc-data-marketplace/Weather_Data/Data_Weather-20240209.csv
[2024-08-14T04:10:57.926+0000] {s3.py:117} INFO - Poking for key : s3://s3-poc-data-marketplace/Weather_Data/Data_Weather-20240209.csv
[2024-08-14T04:11:28.709+0000] {s3.py:117} INFO - Poking for key : s3://s3-poc-data-marketplace/Weather_Data/Data_Weather-20240209.csv
[2024-08-14T04:11:59.356+0000] {s3.py:117} INFO - Poking for key : s3://s3-poc-data-marketplace/Weather_Data/Data_Weather-20240209.csv
[2024-08-14T04:12:30.022+0000] {s3.py:117} INFO - Poking for key : s3://s3-poc-data-marketplace/Weather_Data/Data_Weather-20240209.csv
[2024-08-14T04:12:30.724+0000] {taskinstance.py:441} INFO - ::group::Post task execution logs
[2024-08-14T04:12:30.728+0000] {taskinstance.py:2905} ERROR - Task failed with exception
Traceback (most recent call last):
  File "/home/airflow/.local/lib/python3.12/site-packages/airflow/models/taskinstance.py", line 465, in _execute_task
    result = _execute_callable(context=context, **execute_callable_kwargs)
             ^^^^^^^^^^^^^^^^^^^^^^^^^^^^^^^^^^^^^^^^^^^^^^^^^^^^^^^^^^^^^
  File "/home/airflow/.local/lib/python3.12/site-packages/airflow/models/taskinstance.py", line 432, in _execute_callable
    return execute_callable(context=context, **execute_callable_kwargs)
           ^^^^^^^^^^^^^^^^^^^^^^^^^^^^^^^^^^^^^^^^^^^^^^^^^^^^^^^^^^^^
  File "/home/airflow/.local/lib/python3.12/site-packages/airflow/models/baseoperator.py", line 401, in wrapper
    return func(self, *args, **kwargs)
           ^^^^^^^^^^^^^^^^^^^^^^^^^^^
  File "/home/airflow/.local/lib/python3.12/site-packages/airflow/providers/amazon/aws/sensors/s3.py", line 183, in execute
    super().execute(context)
  File "/home/airflow/.local/lib/python3.12/site-packages/airflow/models/baseoperator.py", line 401, in wrapper
    return func(self, *args, **kwargs)
           ^^^^^^^^^^^^^^^^^^^^^^^^^^^
  File "/home/airflow/.local/lib/python3.12/site-packages/airflow/sensors/base.py", line 281, in execute
    raise AirflowSensorTimeout(message)
airflow.exceptions.AirflowSensorTimeout: Sensor has timed out; run duration of 627.7534649559993 seconds exceeds the specified timeout of 600.0.
[2024-08-14T04:12:30.763+0000] {taskinstance.py:1206} INFO - Immediate failure requested. Marking task as FAILED. dag_id=Weather_Data_Extraction, task_id=check_s3_file, run_id=backfill__2024-02-09T00:00:00+00:00, execution_date=20240209T000000, start_date=20240814T040202, end_date=20240814T041230
[2024-08-14T04:12:30.812+0000] {standard_task_runner.py:110} ERROR - Failed to execute job 522 for task check_s3_file (Sensor has timed out; run duration of 627.7534649559993 seconds exceeds the specified timeout of 600.0.; 1822)
[2024-08-14T04:12:30.879+0000] {local_task_job_runner.py:240} INFO - Task exited with return code 1
[2024-08-14T04:12:30.962+0000] {taskinstance.py:3503} INFO - 0 downstream tasks scheduled from follow-on schedule check
[2024-08-14T04:12:30.968+0000] {local_task_job_runner.py:222} INFO - ::endgroup::
